Workbook

Sheet Outreach Queue
A1: Dali marketplace outreach queue
A2: 32 source-backed targets. Wave 1 originally planned 24 proposals; one Batch A listing was verified closed, leaving 23 currently sendable. This is a presale learning wave, not a causal test of landing-page lift.
A3: Editable cells are pale yellow. Priority, Send Batch, live check, gross margin, and Data Check are system-driven. Landing links contain only an opaque marketplace reference; no-link diagnostic rows must not receive a page URL. In Vercel Analytics, ref=uw-ID maps to /_ref/upwork-ID and ref=fl-ID maps to /_ref/fl-ID. Mark Page View Yes only after that path appears. Recheck every listing in-platform before sending. Do not begin work until the selected blueprint or pilot milestone is accepted and funded.
A5: Wave | B5: Wave Variant | C5: Stage | D5: Group | E5: Priority | F5: Record Key | G5: Match Score | H5: Platform | I5: Title | J5: Budget | K5: Competition | L5: Posted | M5: Observed Pain | N5: Pilot Boundary | O5: Copy-ready Outreach Message | P5: Tracking Landing URL | Q5: Listing URL | R5: Confidence / Red Flag | S5: Sent Date | T5: Page View | U5: Reply Date | V5: Objection | W5: Notes | X5: Qualification | Y5: Sales Path | Z5: Quoted Amount | AA5: Funded Amount | AB5: Archive Reason | AC5: Delivery Hours | AD5: Direct Cost | AE5: Gross Margin % | AF5: Next Follow-up | AG5: Send Batch | AH5: Live Check | AI5: Live Check Note | AJ5: Checked At | AK5: Data Check
A6: Wave 1 | B6: Landing Link | C6: Not Sent | D6: Lead Response | E6: =IF(G6>=90,"A",IF(G6>=80,"B",IF(G6>=70,"C","D"))) | F6: Upwork:~022079500683280398086 | G6: 95 | H6: Upwork | I6: Agentic AI Automation Engineer | J6: Hourly: $40.00 - $75.00 | K6: 50+ | L6: last week | M6: Manual lead intake, CRM updates, and follow-up need to become a reliable agentic process that extracts, classifies, updates CRM, sends a summary, and escalates uncertain cases. | N6: One lead source cluster, one first-reply playbook, one CRM or calendar action path, and visible human approval; exclude outbound prospecting and autonomous pricing. | O6: You want manual lead intake, CRM updates, and follow-up turned into a reliable agentic process with extraction, classification, summaries, and human handoff. We already have a production-ready product core for this at Dali Agency (lead-response core): intake → extract/classify → CRM or calendar action → draft or first reply → human approval on uncertain/pricing cases. We are not starting from a blank repo. The paid work is customization under your stack: your lead sources, CRM fields, qualification rules, and which cases must always stop for a person. First customization pilot I would lock: one lead source cluster, one first-reply playbook, one CRM/calendar action, visible approval on uncertain cases. Packaged boundary + how we run that pilot: https://dali.agents.ge/for/upwork/lead-response?ref=uw-022079500683280398086 If that matches, reply here in Upwork with primary intake channel, CRM, and the lead classes that must always wait for a person. I will confirm fit and send a fixed pilot milestone (or a short paid blueprint if scope is still loose) before any implementation starts. | P6: https://dali.agents.ge/for/upwork/lead-response?ref=uw-022079500683280398086 | Q6: https://www.upwork.com/jobs/span-class-highlight-Agentic-span-span-class-highlight-span-span-class-highlight-Automation-span-Engineer_~022079500683280398086/?referrer_url_path=/nx/search/jobs/ | R6: High confidence; 50+ proposals and a mismatch between metadata hours and description hours. | T6: Unknown | X6: Not Evaluated | Y6: Unassigned | AE6: =IFERROR((AA6-AD6)/AA6,"") | AG6: Batch B | AH6: Manual Check | AI6: Anonymous direct page was blocked by a Cloudflare challenge. Verify open status and scope inside Upwork. | AJ6: 2026-07-30 03:13 +04 | AK6: =IF(AND(U6<>"",S6=""),"WARN: Reply date without sent date",IF(AND(OR(C6="Sent",C6="Replied",C6="Qualified",C6="Blueprint Proposed",C6="Pilot Proposed",C6="Blueprint Funded",C6="Pilot Funded",C6="Won"),S6=""),"WARN: Stage requires sent date",IF(AND(OR(C6="Replied",C6="Qualified",C6="Blueprint Proposed",C6="Pilot Proposed",C6="Blueprint Funded",C6="Pilot Funded",C6="Won"),U6=""),"WARN: Stage requires reply date",IF(AND(X6="Qualified",U6=""),"WARN: Qualified without reply date",IF(AND(C6="Qualified",X6<>"Qualified"),"WARN: Qualified stage mismatch",IF(AND(X6="Qualified",NOT(OR(C6="Qualified",C6="Blueprint Proposed",C6="Pilot Proposed",C6="Blueprint Funded",C6="Pilot Funded",C6="Won"))),"WARN: Qualified value stage mismatch",IF(AND(Z6>0,NOT(OR(Y6="Blueprint",Y6="Direct Pilot"))),"WARN: Quote without sales path",IF(AND(OR(C6="Blueprint Proposed",C6="Blueprint Funded"),Y6<>"Blueprint"),"WARN: Blueprint stage path mismatch",IF(AND(OR(C6="Pilot Proposed",C6="Pilot Funded"),Y6<>"Direct Pilot"),"WARN: Pilot stage path mismatch",IF(AND(OR(C6="Blueprint Proposed",C6="Pilot Proposed",C6="Blueprint Funded",C6="Pilot Funded",C6="Won"),Z6<=0),"WARN: Offer stage without quote",IF(AND(Z6>0,NOT(OR(C6="Blueprint Proposed",C6="Pilot Proposed",C6="Blueprint Funded",C6="Pilot Funded",C6="Won"))),"WARN: Quote stage mismatch",IF(AND(AA6>0,Z6<=0),"WARN: Funded without quote",IF(AND(OR(C6="Blueprint Funded",C6="Pilot Funded",C6="Won"),AA6<=0),"WARN: Funded stage without amount",IF(AND(AA6>0,NOT(OR(C6="Blueprint Funded",C6="Pilot Funded",C6="Won"))),"WARN: Funded value stage mismatch","OK"))))))))))))))
A7: Wave 1 | B7: Landing Link | C7: Not Sent | D7: Lead Response | E7: =IF(G7>=90,"A",IF(G7>=80,"B",IF(G7>=70,"C","D"))) | F7: Upwork:~022082094672185738150 | G7: 95 | H7: Upwork | I7: AI Agent / CRM System Setup | J7: Hourly: $22-$29 | K7: 50+ | L7: 4 hours ago | M7: Follow-up across Gmail, Monday, and Slack must keep replies, history, next contact, reminders, summaries, and drafts in sync while blocking duplicates and do-not-contact contacts. | N7: One inbound communication flow, one history store, one next-contact rule, and one reminder or draft output; exclude broader CRM redesign. | O7: Your brief is follow-up automation across Gmail, Monday, and Slack: reply tracking, next-contact history, reminders, and draft emails without duplicates or do-not-contact misses. We already have a production-ready product core for this at Dali Agency (lead-response core): intake → extract/classify → CRM or calendar action → draft or first reply → human approval on uncertain/pricing cases. We are not starting from a blank repo. The paid work is customization under your stack: your lead sources, CRM fields, qualification rules, and which cases must always stop for a person. First customization pilot I would lock: one inbound communication flow, one history store, one next-contact rule, and one reminder or draft path with human approval on sensitive sends. Packaged boundary + how we run that pilot: https://dali.agents.ge/for/upwork/lead-response?ref=uw-022082094672185738150 If that matches, reply here in Upwork with primary intake channel, CRM, and the lead classes that must always wait for a person. I will confirm fit and send a fixed pilot milestone (or a short paid blueprint if scope is still loose) before any implementation starts. | P7: https://dali.agents.ge/for/upwork/lead-response?ref=uw-022082094672185738150 | Q7: https://www.upwork.com/jobs/Agent-CRM-System-Setup_~022082094672185738150/?referrer_url_path=find_work_home | R7: High confidence; integrations and API permissions are not pinned down, with 50+ proposals and a low rate. | T7: Unknown | X7: Not Evaluated | Y7: Unassigned | AE7: =IFERROR((AA7-AD7)/AA7,"") | AG7: Batch A | AH7: Manual Check | AI7: Anonymous Upwork view exposed a private-listing status but not the brief. Confirm inside the working account; skip if it remains private. | AJ7: 2026-07-30 03:15 +04 | AK7: =IF(AND(U7<>"",S7=""),"WARN: Reply date without sent date",IF(AND(OR(C7="Sent",C7="Replied",C7="Qualified",C7="Blueprint Proposed",C7="Pilot Proposed",C7="Blueprint Funded",C7="Pilot Funded",C7="Won"),S7=""),"WARN: Stage requires sent date",IF(AND(OR(C7="Replied",C7="Qualified",C7="Blueprint Proposed",C7="Pilot Proposed",C7="Blueprint Funded",C7="Pilot Funded",C7="Won"),U7=""),"WARN: Stage requires reply date",IF(AND(X7="Qualified",U7=""),"WARN: Qualified without reply date",IF(AND(C7="Qualified",X7<>"Qualified"),"WARN: Qualified stage mismatch",IF(AND(X7="Qualified",NOT(OR(C7="Qualified",C7="Blueprint Proposed",C7="Pilot Proposed",C7="Blueprint Funded",C7="Pilot Funded",C7="Won"))),"WARN: Qualified value stage mismatch",IF(AND(Z7>0,NOT(OR(Y7="Blueprint",Y7="Direct Pilot"))),"WARN: Quote without sales path",IF(AND(OR(C7="Blueprint Proposed",C7="Blueprint Funded"),Y7<>"Blueprint"),"WARN: Blueprint stage path mismatch",IF(AND(OR(C7="Pilot Proposed",C7="Pilot Funded"),Y7<>"Direct Pilot"),"WARN: Pilot stage path mismatch",IF(AND(OR(C7="Blueprint Proposed",C7="Pilot Proposed",C7="Blueprint Funded",C7="Pilot Funded",C7="Won"),Z7<=0),"WARN: Offer stage without quote",IF(AND(Z7>0,NOT(OR(C7="Blueprint Proposed",C7="Pilot Proposed",C7="Blueprint Funded",C7="Pilot Funded",C7="Won"))),"WARN: Quote stage mismatch",IF(AND(AA7>0,Z7<=0),"WARN: Funded without quote",IF(AND(OR(C7="Blueprint Funded",C7="Pilot Funded",C7="Won"),AA7<=0),"WARN: Funded stage without amount",IF(AND(AA7>0,NOT(OR(C7="Blueprint Funded",C7="Pilot Funded",C7="Won"))),"WARN: Funded value stage mismatch","OK"))))))))))))))
A8: Wave 1 | B8: Landing Link | C8: Not Sent | D8: Lead Response | E8: =IF(G8>=90,"A",IF(G8>=80,"B",IF(G8>=70,"C","D"))) | F8: Upwork:~022080272851686168921 | G8: 90 | H8: Upwork | I8: AI Agent Developer for Field Service Operations Automation | J8: $550.00 | K8: 50+ | L8: 5 days ago | M8: Field service operations need an agent to read email and forms, classify urgency and location, update CRM, select time and specialist, draft replies, remind, and escalate risk. | N8: One intake path to one CRM update and one scheduling or review path, with approval and audit logs. | O8: Field service ops need an agent that reads email/forms, classifies urgency and location, updates CRM, schedules, drafts replies, and escalates risk. We already have a production-ready product core for this at Dali Agency (lead-response core): intake → extract/classify → CRM or calendar action → draft or first reply → human approval on uncertain/pricing cases. We are not starting from a blank repo. The paid work is customization under your stack: your lead sources, CRM fields, qualification rules, and which cases must always stop for a person. First customization pilot I would lock: one intake path → one CRM update → one scheduling/review path with approval and audit logs. Packaged boundary + how we run that pilot: https://dali.agents.ge/for/upwork/lead-response?ref=uw-022080272851686168921 If that matches, reply here in Upwork with primary intake channel, CRM, and the lead classes that must always wait for a person. I will confirm fit and send a fixed pilot milestone (or a short paid blueprint if scope is still loose) before any implementation starts. | P8: https://dali.agents.ge/for/upwork/lead-response?ref=uw-022080272851686168921 | Q8: https://www.upwork.com/jobs/span-class-highlight-span-span-class-highlight-Agent-span-Developer-for-Field-Service-Operations-span-class-highlight-Automation-span_~022080272851686168921/?referrer_url_path=/nx/search/jobs/ | R8: High confidence; a low fixed budget for Phase 1 and 50+ applicants. | T8: Unknown | X8: Not Evaluated | Y8: Unassigned | AE8: =IFERROR((AA8-AD8)/AA8,"") | AG8: Batch B | AH8: Manual Check | AI8: Anonymous direct page was blocked by a Cloudflare challenge. Verify open status and scope inside Upwork. | AJ8: 2026-07-30 03:13 +04 | AK8: =IF(AND(U8<>"",S8=""),"WARN: Reply date without sent date",IF(AND(OR(C8="Sent",C8="Replied",C8="Qualified",C8="Blueprint Proposed",C8="Pilot Proposed",C8="Blueprint Funded",C8="Pilot Funded",C8="Won"),S8=""),"WARN: Stage requires sent date",IF(AND(OR(C8="Replied",C8="Qualified",C8="Blueprint Proposed",C8="Pilot Proposed",C8="Blueprint Funded",C8="Pilot Funded",C8="Won"),U8=""),"WARN: Stage requires reply date",IF(AND(X8="Qualified",U8=""),"WARN: Qualified without reply date",IF(AND(C8="Qualified",X8<>"Qualified"),"WARN: Qualified stage mismatch",IF(AND(X8="Qualified",NOT(OR(C8="Qualified",C8="Blueprint Proposed",C8="Pilot Proposed",C8="Blueprint Funded",C8="Pilot Funded",C8="Won"))),"WARN: Qualified value stage mismatch",IF(AND(Z8>0,NOT(OR(Y8="Blueprint",Y8="Direct Pilot"))),"WARN: Quote without sales path",IF(AND(OR(C8="Blueprint Proposed",C8="Blueprint Funded"),Y8<>"Blueprint"),"WARN: Blueprint stage path mismatch",IF(AND(OR(C8="Pilot Proposed",C8="Pilot Funded"),Y8<>"Direct Pilot"),"WARN: Pilot stage path mismatch",IF(AND(OR(C8="Blueprint Proposed",C8="Pilot Proposed",C8="Blueprint Funded",C8="Pilot Funded",C8="Won"),Z8<=0),"WARN: Offer stage without quote",IF(AND(Z8>0,NOT(OR(C8="Blueprint Proposed",C8="Pilot Proposed",C8="Blueprint Funded",C8="Pilot Funded",C8="Won"))),"WARN: Quote stage mismatch",IF(AND(AA8>0,Z8<=0),"WARN: Funded without quote",IF(AND(OR(C8="Blueprint Funded",C8="Pilot Funded",C8="Won"),AA8<=0),"WARN: Funded stage without amount",IF(AND(AA8>0,NOT(OR(C8="Blueprint Funded",C8="Pilot Funded",C8="Won"))),"WARN: Funded value stage mismatch","OK"))))))))))))))
A9: Wave 1 | B9: Landing Link | C9: Not Sent | D9: Lead Response | E9: =IF(G9>=90,"A",IF(G9>=80,"B",IF(G9>=70,"C","D"))) | F9: Upwork:~022076935615291863294 | G9: 90 | H9: Upwork | I9: Ai Automation for marketing agency | J9: $900.00 | K9: 50+ | L9: 2 weeks ago | M9: A marketing agency wants AI tied into CRM, email, and project management to qualify leads, support bookings, prepare proposals, and handle handoffs. | N9: One workflow, preferably lead qualification or support handoff, with one acceptance test and expansion only after validation. | O9: Your agency wants AI tied into CRM, email, and PM for lead qualification, bookings, proposals, and handoffs - starting small is the right call. We already have a production-ready product core for this at Dali Agency (lead-response core): intake → extract/classify → CRM or calendar action → draft or first reply → human approval on uncertain/pricing cases. We are not starting from a blank repo. The paid work is customization under your stack: your lead sources, CRM fields, qualification rules, and which cases must always stop for a person. First customization pilot I would lock: one CRM-connected pilot workflow, one acceptance test, one handoff path before proposals or wider automation. Packaged boundary + how we run that pilot: https://dali.agents.ge/for/upwork/lead-response?ref=uw-022076935615291863294 If that matches, reply here in Upwork with primary intake channel, CRM, and the lead classes that must always wait for a person. I will confirm fit and send a fixed pilot milestone (or a short paid blueprint if scope is still loose) before any implementation starts. | P9: https://dali.agents.ge/for/upwork/lead-response?ref=uw-022076935615291863294 | Q9: https://www.upwork.com/jobs/span-class-highlight-span-span-class-highlight-Automation-span-for-marketing-agency_~022076935615291863294/?referrer_url_path=/nx/search/jobs/ | R9: High confidence; no spend or rating yet and 50+ proposals. | T9: Unknown | X9: Not Evaluated | Y9: Unassigned | AE9: =IFERROR((AA9-AD9)/AA9,"") | AG9: Batch C | AH9: Manual Check | AI9: Anonymous direct page was blocked by a Cloudflare challenge. Verify open status and scope inside Upwork. | AJ9: 2026-07-30 03:14 +04 | AK9: =IF(AND(U9<>"",S9=""),"WARN: Reply date without sent date",IF(AND(OR(C9="Sent",C9="Replied",C9="Qualified",C9="Blueprint Proposed",C9="Pilot Proposed",C9="Blueprint Funded",C9="Pilot Funded",C9="Won"),S9=""),"WARN: Stage requires sent date",IF(AND(OR(C9="Replied",C9="Qualified",C9="Blueprint Proposed",C9="Pilot Proposed",C9="Blueprint Funded",C9="Pilot Funded",C9="Won"),U9=""),"WARN: Stage requires reply date",IF(AND(X9="Qualified",U9=""),"WARN: Qualified without reply date",IF(AND(C9="Qualified",X9<>"Qualified"),"WARN: Qualified stage mismatch",IF(AND(X9="Qualified",NOT(OR(C9="Qualified",C9="Blueprint Proposed",C9="Pilot Proposed",C9="Blueprint Funded",C9="Pilot Funded",C9="Won"))),"WARN: Qualified value stage mismatch",IF(AND(Z9>0,NOT(OR(Y9="Blueprint",Y9="Direct Pilot"))),"WARN: Quote without sales path",IF(AND(OR(C9="Blueprint Proposed",C9="Blueprint Funded"),Y9<>"Blueprint"),"WARN: Blueprint stage path mismatch",IF(AND(OR(C9="Pilot Proposed",C9="Pilot Funded"),Y9<>"Direct Pilot"),"WARN: Pilot stage path mismatch",IF(AND(OR(C9="Blueprint Proposed",C9="Pilot Proposed",C9="Blueprint Funded",C9="Pilot Funded",C9="Won"),Z9<=0),"WARN: Offer stage without quote",IF(AND(Z9>0,NOT(OR(C9="Blueprint Proposed",C9="Pilot Proposed",C9="Blueprint Funded",C9="Pilot Funded",C9="Won"))),"WARN: Quote stage mismatch",IF(AND(AA9>0,Z9<=0),"WARN: Funded without quote",IF(AND(OR(C9="Blueprint Funded",C9="Pilot Funded",C9="Won"),AA9<=0),"WARN: Funded stage without amount",IF(AND(AA9>0,NOT(OR(C9="Blueprint Funded",C9="Pilot Funded",C9="Won"))),"WARN: Funded value stage mismatch","OK"))))))))))))))
A10: Wave 1 | B10: Landing Link | C10: Not Sent | D10: Lead Response | E10: =IF(G10>=90,"A",IF(G10>=80,"B",IF(G10>=70,"C","D"))) | F10: Upwork:~022082059740997677549 | G10: 90 | H10: Upwork | I10: Senior AI Engineer to Build an AI Sales Operations Employee (LLMs, CRM, Multi-Agent AI) | J10: Hourly: $30-$45 | K10: 50+ | L10: 6 hours ago | M10: A production AI sales employee must research and qualify leads, generate outreach and proposals, update CRM, follow up, book meetings, and show analytics. | N10: One lead-research-to-CRM loop, one outreach path, one booking handoff, and monitoring. | O10: You are hiring for a production AI sales-ops employee: research/qualify, CRM, outreach, follow-up, booking, analytics. That is a platform end-state, not a day-one blank build. We already have a production-ready product core for this at Dali Agency (lead-response core): intake → extract/classify → CRM or calendar action → draft or first reply → human approval on uncertain/pricing cases. We are not starting from a blank repo. The paid work is customization under your stack: your lead sources, CRM fields, qualification rules, and which cases must always stop for a person. First customization pilot I would lock: one lead-research → qualification → CRM update → booked-meeting handoff path first, with multi-agent layers only after that path is proven. Packaged boundary + how we run that pilot: https://dali.agents.ge/for/upwork/lead-response?ref=uw-022082059740997677549 If that matches, reply here in Upwork with primary intake channel, CRM, and the lead classes that must always wait for a person. I will confirm fit and send a fixed pilot milestone (or a short paid blueprint if scope is still loose) before any implementation starts. | P10: https://dali.agents.ge/for/upwork/lead-response?ref=uw-022082059740997677549 | Q10: https://www.upwork.com/jobs/Senior-Engineer-Build-Sales-Operations-Employee-LLMs-CRM-Multi-Agent_~022082059740997677549/?referrer_url_path=find_work_home | R10: High confidence; large production scope, 3-6 months, 30+ hours per week, and 50+ proposals. | T10: Unknown | X10: Not Evaluated | Y10: Unassigned | AE10: =IFERROR((AA10-AD10)/AA10,"") | AG10: Batch A | AH10: Open | AI10: Full card accessible and scope matched. 50+ proposals and client viewed yesterday. | AJ10: 2026-07-30 03:16 +04 | AK10: =IF(AND(U10<>"",S10=""),"WARN: Reply date without sent date",IF(AND(OR(C10="Sent",C10="Replied",C10="Qualified",C10="Blueprint Proposed",C10="Pilot Proposed",C10="Blueprint Funded",C10="Pilot Funded",C10="Won"),S10=""),"WARN: Stage requires sent date",IF(AND(OR(C10="Replied",C10="Qualified",C10="Blueprint Proposed",C10="Pilot Proposed",C10="Blueprint Funded",C10="Pilot Funded",C10="Won"),U10=""),"WARN: Stage requires reply date",IF(AND(X10="Qualified",U10=""),"WARN: Qualified without reply date",IF(AND(C10="Qualified",X10<>"Qualified"),"WARN: Qualified stage mismatch",IF(AND(X10="Qualified",NOT(OR(C10="Qualified",C10="Blueprint Proposed",C10="Pilot Proposed",C10="Blueprint Funded",C10="Pilot Funded",C10="Won"))),"WARN: Qualified value stage mismatch",IF(AND(Z10>0,NOT(OR(Y10="Blueprint",Y10="Direct Pilot"))),"WARN: Quote without sales path",IF(AND(OR(C10="Blueprint Proposed",C10="Blueprint Funded"),Y10<>"Blueprint"),"WARN: Blueprint stage path mismatch",IF(AND(OR(C10="Pilot Proposed",C10="Pilot Funded"),Y10<>"Direct Pilot"),"WARN: Pilot stage path mismatch",IF(AND(OR(C10="Blueprint Proposed",C10="Pilot Proposed",C10="Blueprint Funded",C10="Pilot Funded",C10="Won"),Z10<=0),"WARN: Offer stage without quote",IF(AND(Z10>0,NOT(OR(C10="Blueprint Proposed",C10="Pilot Proposed",C10="Blueprint Funded",C10="Pilot Funded",C10="Won"))),"WARN: Quote stage mismatch",IF(AND(AA10>0,Z10<=0),"WARN: Funded without quote",IF(AND(OR(C10="Blueprint Funded",C10="Pilot Funded",C10="Won"),AA10<=0),"WARN: Funded stage without amount",IF(AND(AA10>0,NOT(OR(C10="Blueprint Funded",C10="Pilot Funded",C10="Won"))),"WARN: Funded value stage mismatch","OK"))))))))))))))
A11: Wave 1 | B11: Landing Link | C11: Not Sent | D11: Lead Response | E11: =IF(G11>=90,"A",IF(G11>=80,"B",IF(G11>=70,"C","D"))) | F11: Upwork:~022081957032774069874 | G11: 90 | H11: Upwork | I11: AI Automation Developer - Gmail, OpenAI & SMS | J11: Hourly: $15-$35 | K11: 50+ | L11: 13 hours ago | M11: A leasing assistant must read new applications, answer by email and SMS, pre-screen tenants, schedule showings, and log communications. | N11: One leasing workflow: email intake, standard replies, pre-screening, calendar booking, and human review for sensitive decisions. | O11: The leasing assistant brief is email/SMS intake, standard replies, pre-screen, showing booking, and communication log. We already have a production-ready product core for this at Dali Agency (lead-response core): intake → extract/classify → CRM or calendar action → draft or first reply → human approval on uncertain/pricing cases. We are not starting from a blank repo. The paid work is customization under your stack: your lead sources, CRM fields, qualification rules, and which cases must always stop for a person. First customization pilot I would lock: one application flow, one calendar path, human review for any sensitive tenant decision. Packaged boundary + how we run that pilot: https://dali.agents.ge/for/upwork/lead-response?ref=uw-022081957032774069874 If that matches, reply here in Upwork with primary intake channel, CRM, and the lead classes that must always wait for a person. I will confirm fit and send a fixed pilot milestone (or a short paid blueprint if scope is still loose) before any implementation starts. | P11: https://dali.agents.ge/for/upwork/lead-response?ref=uw-022081957032774069874 | Q11: https://www.upwork.com/jobs/Automation-Developer-Gmail-OpenAI-SMS_~022081957032774069874/?referrer_url_path=find_work_home | R11: High confidence; privacy-sensitive tenant screening and 50+ proposals. | T11: Unknown | X11: Not Evaluated | Y11: Unassigned | AE11: =IFERROR((AA11-AD11)/AA11,"") | AG11: Batch B | AH11: Manual Check | AI11: Anonymous direct page was blocked by a Cloudflare challenge. Verify open status and scope inside Upwork. | AJ11: 2026-07-30 03:13 +04 | AK11: =IF(AND(U11<>"",S11=""),"WARN: Reply date without sent date",IF(AND(OR(C11="Sent",C11="Replied",C11="Qualified",C11="Blueprint Proposed",C11="Pilot Proposed",C11="Blueprint Funded",C11="Pilot Funded",C11="Won"),S11=""),"WARN: Stage requires sent date",IF(AND(OR(C11="Replied",C11="Qualified",C11="Blueprint Proposed",C11="Pilot Proposed",C11="Blueprint Funded",C11="Pilot Funded",C11="Won"),U11=""),"WARN: Stage requires reply date",IF(AND(X11="Qualified",U11=""),"WARN: Qualified without reply date",IF(AND(C11="Qualified",X11<>"Qualified"),"WARN: Qualified stage mismatch",IF(AND(X11="Qualified",NOT(OR(C11="Qualified",C11="Blueprint Proposed",C11="Pilot Proposed",C11="Blueprint Funded",C11="Pilot Funded",C11="Won"))),"WARN: Qualified value stage mismatch",IF(AND(Z11>0,NOT(OR(Y11="Blueprint",Y11="Direct Pilot"))),"WARN: Quote without sales path",IF(AND(OR(C11="Blueprint Proposed",C11="Blueprint Funded"),Y11<>"Blueprint"),"WARN: Blueprint stage path mismatch",IF(AND(OR(C11="Pilot Proposed",C11="Pilot Funded"),Y11<>"Direct Pilot"),"WARN: Pilot stage path mismatch",IF(AND(OR(C11="Blueprint Proposed",C11="Pilot Proposed",C11="Blueprint Funded",C11="Pilot Funded",C11="Won"),Z11<=0),"WARN: Offer stage without quote",IF(AND(Z11>0,NOT(OR(C11="Blueprint Proposed",C11="Pilot Proposed",C11="Blueprint Funded",C11="Pilot Funded",C11="Won"))),"WARN: Quote stage mismatch",IF(AND(AA11>0,Z11<=0),"WARN: Funded without quote",IF(AND(OR(C11="Blueprint Funded",C11="Pilot Funded",C11="Won"),AA11<=0),"WARN: Funded stage without amount",IF(AND(AA11>0,NOT(OR(C11="Blueprint Funded",C11="Pilot Funded",C11="Won"))),"WARN: Funded value stage mismatch","OK"))))))))))))))
A12: Wave 1 | B12: Landing Link | C12: Not Sent | D12: Lead Response | E12: =IF(G12>=90,"A",IF(G12>=80,"B",IF(G12>=70,"C","D"))) | F12: Upwork:~022071869598491167955 | G12: 90 | H12: Upwork | I12: AI Automation Specialist for Lead Qualification, CRM Routing and Multichannel Appointment Booking | J12: $500.00 | K12: 20 to 50 | L12: 4 weeks ago | M12: A multilingual appointment system must classify messages, manage booking changes, reminders, and waitlists, sync calendar and CRM, and escalate when needed. | N12: One language, one appointment flow, one CRM and calendar integration, and explicit escalation rules. | O12: You need multilingual lead qualification, CRM routing, and multichannel appointment booking with reschedules, reminders, and waitlists. We already have a production-ready product core for this at Dali Agency (lead-response core): intake → extract/classify → CRM or calendar action → draft or first reply → human approval on uncertain/pricing cases. We are not starting from a blank repo. The paid work is customization under your stack: your lead sources, CRM fields, qualification rules, and which cases must always stop for a person. First customization pilot I would lock: one language first, one appointment flow, one CRM+calendar integration, explicit escalation rules. Packaged boundary + how we run that pilot: https://dali.agents.ge/for/upwork/lead-response?ref=uw-022071869598491167955 If that matches, reply here in Upwork with primary intake channel, CRM, and the lead classes that must always wait for a person. I will confirm fit and send a fixed pilot milestone (or a short paid blueprint if scope is still loose) before any implementation starts. | P12: https://dali.agents.ge/for/upwork/lead-response?ref=uw-022071869598491167955 | Q12: https://www.upwork.com/jobs/span-class-highlight-span-span-class-highlight-Automation-span-Specialist-for-Lead-Qualification-CRM-Routing-and-Multichannel-Appointment-Booking_~022071869598491167955/?referrer_url_path=/nx/search/jobs/ | R12: High confidence; the fixed $500 scope is too small for a multi-stage system. | T12: Unknown | X12: Not Evaluated | Y12: Unassigned | AE12: =IFERROR((AA12-AD12)/AA12,"") | AG12: Batch C | AH12: Manual Check | AI12: Anonymous direct page was blocked by a Cloudflare challenge. Verify open status and scope inside Upwork. | AJ12: 2026-07-30 03:14 +04 | AK12: =IF(AND(U12<>"",S12=""),"WARN: Reply date without sent date",IF(AND(OR(C12="Sent",C12="Replied",C12="Qualified",C12="Blueprint Proposed",C12="Pilot Proposed",C12="Blueprint Funded",C12="Pilot Funded",C12="Won"),S12=""),"WARN: Stage requires sent date",IF(AND(OR(C12="Replied",C12="Qualified",C12="Blueprint Proposed",C12="Pilot Proposed",C12="Blueprint Funded",C12="Pilot Funded",C12="Won"),U12=""),"WARN: Stage requires reply date",IF(AND(X12="Qualified",U12=""),"WARN: Qualified without reply date",IF(AND(C12="Qualified",X12<>"Qualified"),"WARN: Qualified stage mismatch",IF(AND(X12="Qualified",NOT(OR(C12="Qualified",C12="Blueprint Proposed",C12="Pilot Proposed",C12="Blueprint Funded",C12="Pilot Funded",C12="Won"))),"WARN: Qualified value stage mismatch",IF(AND(Z12>0,NOT(OR(Y12="Blueprint",Y12="Direct Pilot"))),"WARN: Quote without sales path",IF(AND(OR(C12="Blueprint Proposed",C12="Blueprint Funded"),Y12<>"Blueprint"),"WARN: Blueprint stage path mismatch",IF(AND(OR(C12="Pilot Proposed",C12="Pilot Funded"),Y12<>"Direct Pilot"),"WARN: Pilot stage path mismatch",IF(AND(OR(C12="Blueprint Proposed",C12="Pilot Proposed",C12="Blueprint Funded",C12="Pilot Funded",C12="Won"),Z12<=0),"WARN: Offer stage without quote",IF(AND(Z12>0,NOT(OR(C12="Blueprint Proposed",C12="Pilot Proposed",C12="Blueprint Funded",C12="Pilot Funded",C12="Won"))),"WARN: Quote stage mismatch",IF(AND(AA12>0,Z12<=0),"WARN: Funded without quote",IF(AND(OR(C12="Blueprint Funded",C12="Pilot Funded",C12="Won"),AA12<=0),"WARN: Funded stage without amount",IF(AND(AA12>0,NOT(OR(C12="Blueprint Funded",C12="Pilot Funded",C12="Won"))),"WARN: Funded value stage mismatch","OK"))))))))))))))
A13: Wave 1 | B13: No-Link Diagnostic | C13: Not Sent | D13: Lead Response | E13: =IF(G13>=90,"A",IF(G13>=80,"B",IF(G13>=70,"C","D"))) | F13: Upwork:~022082076899341845245 | G13: 85 | H13: Upwork | I13: Full Stack AI Automation Engineer Ai Sales Workflow Platform | J13: Hourly: $25-$47 | K13: 50+ | L13: 5 hours ago | M13: A high-volume service business needs an AI sales agent that qualifies leads, updates GoHighLevel, assigns a manager, follows up, books meetings, and prepares call summaries. | N13: One lead source to one CRM action path, booking handoff, and pre-call summary. | O13: You already have a clear sales-ops workflow: qualify, update GoHighLevel, assign the manager, follow up, and book meetings. We already have a production-ready product core for this at Dali Agency (lead-response core): intake → extract/classify → CRM or calendar action → draft or first reply → human approval on uncertain/pricing cases. We are not starting from a blank repo. The paid work is customization under your stack: your lead sources, CRM fields, qualification rules, and which cases must always stop for a person. First customization pilot I would lock: one lead source, one GoHighLevel action path, one manager assignment rule, and human approval on edge cases. If that matches, reply here in Upwork with primary intake channel, CRM, and the lead classes that must always wait for a person. I will confirm fit and send a fixed pilot milestone (or a short paid blueprint if scope is still loose) before any implementation starts. | P13: No link in diagnostic proposal | Q13: https://www.upwork.com/jobs/Full-Stack-Automation-Engineer-Sales-Workflow-Platform_~022082076899341845245/?referrer_url_path=find_work_home | R13: High confidence; 3-6 month scope, 50+ proposals, and no proven payment history. | T13: Unknown | X13: Not Evaluated | Y13: Unassigned | AE13: =IFERROR((AA13-AD13)/AA13,"") | AG13: Batch A | AH13: Open | AI13: Full card accessible and scope matched. 50+ proposals, client viewed yesterday, one interview. | AJ13: 2026-07-30 03:15 +04 | AK13: =IF(AND(U13<>"",S13=""),"WARN: Reply date without sent date",IF(AND(OR(C13="Sent",C13="Replied",C13="Qualified",C13="Blueprint Proposed",C13="Pilot Proposed",C13="Blueprint Funded",C13="Pilot Funded",C13="Won"),S13=""),"WARN: Stage requires sent date",IF(AND(OR(C13="Replied",C13="Qualified",C13="Blueprint Proposed",C13="Pilot Proposed",C13="Blueprint Funded",C13="Pilot Funded",C13="Won"),U13=""),"WARN: Stage requires reply date",IF(AND(X13="Qualified",U13=""),"WARN: Qualified without reply date",IF(AND(C13="Qualified",X13<>"Qualified"),"WARN: Qualified stage mismatch",IF(AND(X13="Qualified",NOT(OR(C13="Qualified",C13="Blueprint Proposed",C13="Pilot Proposed",C13="Blueprint Funded",C13="Pilot Funded",C13="Won"))),"WARN: Qualified value stage mismatch",IF(AND(Z13>0,NOT(OR(Y13="Blueprint",Y13="Direct Pilot"))),"WARN: Quote without sales path",IF(AND(OR(C13="Blueprint Proposed",C13="Blueprint Funded"),Y13<>"Blueprint"),"WARN: Blueprint stage path mismatch",IF(AND(OR(C13="Pilot Proposed",C13="Pilot Funded"),Y13<>"Direct Pilot"),"WARN: Pilot stage path mismatch",IF(AND(OR(C13="Blueprint Proposed",C13="Pilot Proposed",C13="Blueprint Funded",C13="Pilot Funded",C13="Won"),Z13<=0),"WARN: Offer stage without quote",IF(AND(Z13>0,NOT(OR(C13="Blueprint Proposed",C13="Pilot Proposed",C13="Blueprint Funded",C13="Pilot Funded",C13="Won"))),"WARN: Quote stage mismatch",IF(AND(AA13>0,Z13<=0),"WARN: Funded without quote",IF(AND(OR(C13="Blueprint Funded",C13="Pilot Funded",C13="Won"),AA13<=0),"WARN: Funded stage without amount",IF(AND(AA13>0,NOT(OR(C13="Blueprint Funded",C13="Pilot Funded",C13="Won"))),"WARN: Funded value stage mismatch","OK"))))))))))))))
A14: Hold | B14: Hold | C14: Hold | D14: Lead Response | E14: =IF(G14>=90,"A",IF(G14>=80,"B",IF(G14>=70,"C","D"))) | F14: Upwork:~022082023362208208284 | G14: 85 | H14: Upwork | I14: AI Agent & n8n Automation System for Freight Forwarding Company | J14: Hourly | K14: 20 to 50 | L14: 5 hours ago | M14: Freight-forwarding leads need dedupe, CRM status updates, email sequences, and reporting before later freight calculations. | N14: One lead intake to dedupe, CRM status, one email sequence, and one report. | O14: I would ship one lead-to-follow-up path first: lead intake, dedupe, CRM status, sequence email, report. Freight calculation can wait. I packaged that exact pilot boundary here: https://dali.agents.ge/for/upwork/lead-response?ref=uw-022082023362208208284 If that boundary matches your brief, reply here in Upwork with your primary intake channel, CRM, and the lead classes that must always wait for a person. I will turn those inputs into the first replay set and pass/fail acceptance test before implementation. | P14: https://dali.agents.ge/for/upwork/lead-response?ref=uw-022082023362208208284 | Q14: https://www.upwork.com/jobs/span-class-highlight-span-span-class-highlight-Agent-span-amp-n8n-span-class-highlight-Automation-span-System-for-Freight-Forwarding-Company_~022082023362208208284/?referrer_url_path=/nx/search/jobs/ | R14: High confidence; future RFQ and freight-calculation scope should stay outside the pilot. | T14: Unknown | X14: Not Evaluated | Y14: Hold | AE14: =IFERROR((AA14-AD14)/AA14,"") | AG14: Hold | AH14: Not Checked | AI14: Hold row; not part of the current live-listing audit. | AK14: =IF(AND(U14<>"",S14=""),"WARN: Reply date without sent date",IF(AND(OR(C14="Sent",C14="Replied",C14="Qualified",C14="Blueprint Proposed",C14="Pilot Proposed",C14="Blueprint Funded",C14="Pilot Funded",C14="Won"),S14=""),"WARN: Stage requires sent date",IF(AND(OR(C14="Replied",C14="Qualified",C14="Blueprint Proposed",C14="Pilot Proposed",C14="Blueprint Funded",C14="Pilot Funded",C14="Won"),U14=""),"WARN: Stage requires reply date",IF(AND(X14="Qualified",U14=""),"WARN: Qualified without reply date",IF(AND(C14="Qualified",X14<>"Qualified"),"WARN: Qualified stage mismatch",IF(AND(X14="Qualified",NOT(OR(C14="Qualified",C14="Blueprint Proposed",C14="Pilot Proposed",C14="Blueprint Funded",C14="Pilot Funded",C14="Won"))),"WARN: Qualified value stage mismatch",IF(AND(Z14>0,NOT(OR(Y14="Blueprint",Y14="Direct Pilot"))),"WARN: Quote without sales path",IF(AND(OR(C14="Blueprint Proposed",C14="Blueprint Funded"),Y14<>"Blueprint"),"WARN: Blueprint stage path mismatch",IF(AND(OR(C14="Pilot Proposed",C14="Pilot Funded"),Y14<>"Direct Pilot"),"WARN: Pilot stage path mismatch",IF(AND(OR(C14="Blueprint Proposed",C14="Pilot Proposed",C14="Blueprint Funded",C14="Pilot Funded",C14="Won"),Z14<=0),"WARN: Offer stage without quote",IF(AND(Z14>0,NOT(OR(C14="Blueprint Proposed",C14="Pilot Proposed",C14="Blueprint Funded",C14="Pilot Funded",C14="Won"))),"WARN: Quote stage mismatch",IF(AND(AA14>0,Z14<=0),"WARN: Funded without quote",IF(AND(OR(C14="Blueprint Funded",C14="Pilot Funded",C14="Won"),AA14<=0),"WARN: Funded stage without amount",IF(AND(AA14>0,NOT(OR(C14="Blueprint Funded",C14="Pilot Funded",C14="Won"))),"WARN: Funded value stage mismatch","OK"))))))))))))))
A15: Hold | B15: Hold | C15: Hold | D15: Lead Response | E15: =IF(G15>=90,"A",IF(G15>=80,"B",IF(G15>=70,"C","D"))) | F15: Upwork:~022080037748505517610 | G15: 75 | H15: Upwork | I15: Agentic AI Customer Support System for Real Estate Business | J15: $200.00 | K15: 20 to 50 | L15: 5 days ago | M15: A real-estate sales agent must answer questions, qualify leads, handle objections, book meetings, and send conversation history to CRM, with chat and possibly voice. | N15: One channel, one qualification flow, and one CRM handoff; defer voice until the chat path is stable. | O15: I saw the real-estate sales-agent brief as a chat-first qualification and booking system with CRM handoff. I would keep the first pilot to one channel, one objection path, and one clean handoff before adding voice. I packaged that exact pilot boundary here: https://dali.agents.ge/for/upwork/lead-response?ref=uw-022080037748505517610 If that boundary matches your brief, reply here in Upwork with your primary intake channel, CRM, and the lead classes that must always wait for a person. I will turn those inputs into the first replay set and pass/fail acceptance test before implementation. | P15: https://dali.agents.ge/for/upwork/lead-response?ref=uw-022080037748505517610 | Q15: https://www.upwork.com/jobs/span-class-highlight-Agentic-span-span-class-highlight-span-Customer-Support-System-for-Real-Estate-Business_~022080037748505517610/?referrer_url_path=/nx/search/jobs/ | R15: High confidence; the $200 budget and requirement for proven sales-agent or voice examples make this a holdout. | T15: Unknown | X15: Not Evaluated | Y15: Hold | AE15: =IFERROR((AA15-AD15)/AA15,"") | AG15: Hold | AH15: Not Checked | AI15: Hold row; not part of the current live-listing audit. | AK15: =IF(AND(U15<>"",S15=""),"WARN: Reply date without sent date",IF(AND(OR(C15="Sent",C15="Replied",C15="Qualified",C15="Blueprint Proposed",C15="Pilot Proposed",C15="Blueprint Funded",C15="Pilot Funded",C15="Won"),S15=""),"WARN: Stage requires sent date",IF(AND(OR(C15="Replied",C15="Qualified",C15="Blueprint Proposed",C15="Pilot Proposed",C15="Blueprint Funded",C15="Pilot Funded",C15="Won"),U15=""),"WARN: Stage requires reply date",IF(AND(X15="Qualified",U15=""),"WARN: Qualified without reply date",IF(AND(C15="Qualified",X15<>"Qualified"),"WARN: Qualified stage mismatch",IF(AND(X15="Qualified",NOT(OR(C15="Qualified",C15="Blueprint Proposed",C15="Pilot Proposed",C15="Blueprint Funded",C15="Pilot Funded",C15="Won"))),"WARN: Qualified value stage mismatch",IF(AND(Z15>0,NOT(OR(Y15="Blueprint",Y15="Direct Pilot"))),"WARN: Quote without sales path",IF(AND(OR(C15="Blueprint Proposed",C15="Blueprint Funded"),Y15<>"Blueprint"),"WARN: Blueprint stage path mismatch",IF(AND(OR(C15="Pilot Proposed",C15="Pilot Funded"),Y15<>"Direct Pilot"),"WARN: Pilot stage path mismatch",IF(AND(OR(C15="Blueprint Proposed",C15="Pilot Proposed",C15="Blueprint Funded",C15="Pilot Funded",C15="Won"),Z15<=0),"WARN: Offer stage without quote",IF(AND(Z15>0,NOT(OR(C15="Blueprint Proposed",C15="Pilot Proposed",C15="Blueprint Funded",C15="Pilot Funded",C15="Won"))),"WARN: Quote stage mismatch",IF(AND(AA15>0,Z15<=0),"WARN: Funded without quote",IF(AND(OR(C15="Blueprint Funded",C15="Pilot Funded",C15="Won"),AA15<=0),"WARN: Funded stage without amount",IF(AND(AA15>0,NOT(OR(C15="Blueprint Funded",C15="Pilot Funded",C15="Won"))),"WARN: Funded value stage mismatch","OK"))))))))))))))
A16: Wave 1 | B16: Landing Link | C16: Not Sent | D16: Client Inbox | E16: =IF(G16>=90,"A",IF(G16>=80,"B",IF(G16>=70,"C","D"))) | F16: FL.ru:5515592 | G16: 95 | H16: FL.ru | I16: Внедрение ИИ-агента для автоматизации переписок с клиентами | J16: по договоренности | K16: 26 | L16: not saved | M16: Агент для переписки в мессенджерах и по email с интеграцией в коробочный Битрикс24. | N16: Один сценарий переписки, один контур Битрикс24, ручное подтверждение и понятные правила доступа. | O16: Нужен ИИ-агент для переписок в мессенджерах и email с интеграцией в коробочный Битрикс24. У нас в Dali Agency уже собрано готовое продуктовое ядро client-inbox: входящее сообщение → утвержденные источники → черновик ответа + история → разрешенные действия → эскалация, если нет опоры. Мы не пишем систему с нуля. Оплачиваемая работа - кастомизация под вас: ваш канал, CRM, базу ответов и действия, которые требуют подтверждения человеком. Первый пилот кастомизации, который я бы зафиксировал: один канал, один workflow: входящее → черновик ответа → ручное подтверждение → запись в Битрикс24. Упакованная граница пилота и как мы это ведем: https://dali.agents.ge/ru/solutions/client-inbox?ref=fl-5515592 Если граница совпадает, ответьте здесь в проекте FL.ru и пришлите один канал, один набор утвержденных источников и действия, которые всегда ждут человека. Я подтвержу fit и пришлю фиксированный milestone пилота (или короткий платный blueprint, если scope еще рыхлый) до начала реализации. | P16: https://dali.agents.ge/ru/solutions/client-inbox?ref=fl-5515592 | Q16: https://www.fl.ru/projects/5515592/vnedrenie-ii-agenta-dlya-avtomatizatsii-perepisok-s-klientami.html | R16: High confidence; 26 ответов, бюджет не указан, privacy, доступы к CRM и approval не описаны. | T16: Unknown | X16: Not Evaluated | Y16: Unassigned | AE16: =IFERROR((AA16-AD16)/AA16,"") | AG16: Batch A | AH16: Open | AI16: Direct page returned 200 with an active response CTA; title and scope matched. | AJ16: 2026-07-30 03:13 +04 | AK16: =IF(AND(U16<>"",S16=""),"WARN: Reply date without sent date",IF(AND(OR(C16="Sent",C16="Replied",C16="Qualified",C16="Blueprint Proposed",C16="Pilot Proposed",C16="Blueprint Funded",C16="Pilot Funded",C16="Won"),S16=""),"WARN: Stage requires sent date",IF(AND(OR(C16="Replied",C16="Qualified",C16="Blueprint Proposed",C16="Pilot Proposed",C16="Blueprint Funded",C16="Pilot Funded",C16="Won"),U16=""),"WARN: Stage requires reply date",IF(AND(X16="Qualified",U16=""),"WARN: Qualified without reply date",IF(AND(C16="Qualified",X16<>"Qualified"),"WARN: Qualified stage mismatch",IF(AND(X16="Qualified",NOT(OR(C16="Qualified",C16="Blueprint Proposed",C16="Pilot Proposed",C16="Blueprint Funded",C16="Pilot Funded",C16="Won"))),"WARN: Qualified value stage mismatch",IF(AND(Z16>0,NOT(OR(Y16="Blueprint",Y16="Direct Pilot"))),"WARN: Quote without sales path",IF(AND(OR(C16="Blueprint Proposed",C16="Blueprint Funded"),Y16<>"Blueprint"),"WARN: Blueprint stage path mismatch",IF(AND(OR(C16="Pilot Proposed",C16="Pilot Funded"),Y16<>"Direct Pilot"),"WARN: Pilot stage path mismatch",IF(AND(OR(C16="Blueprint Proposed",C16="Pilot Proposed",C16="Blueprint Funded",C16="Pilot Funded",C16="Won"),Z16<=0),"WARN: Offer stage without quote",IF(AND(Z16>0,NOT(OR(C16="Blueprint Proposed",C16="Pilot Proposed",C16="Blueprint Funded",C16="Pilot Funded",C16="Won"))),"WARN: Quote stage mismatch",IF(AND(AA16>0,Z16<=0),"WARN: Funded without quote",IF(AND(OR(C16="Blueprint Funded",C16="Pilot Funded",C16="Won"),AA16<=0),"WARN: Funded stage without amount",IF(AND(AA16>0,NOT(OR(C16="Blueprint Funded",C16="Pilot Funded",C16="Won"))),"WARN: Funded value stage mismatch","OK"))))))))))))))
A17: Wave 1 | B17: Landing Link | C17: Not Sent | D17: Client Inbox | E17: =IF(G17>=90,"A",IF(G17>=80,"B",IF(G17>=70,"C","D"))) | F17: Upwork:~022069443845701876220 | G17: 95 | H17: Upwork | I17: AI Automation Engineer: Build a Custom Claude Customer Service Agent | J17: Hourly: $40.00 - $80.00 | K17: 50+ | L17: last month | M17: A production Claude customer-service agent must match the team tone, work with files and internal knowledge, send email, update CRM, run only approved workflows, and escalate sensitive actions. | N17: One customer channel, one approved answer and action policy, one CRM history path, one knowledge or file source set, and human review for sensitive actions. | O17: This is not "just a chatbot": controlled customer responses across approved knowledge, files, email, and CRM, with sensitive actions stopped for review. We already have a production-ready product core for this at Dali Agency (client-inbox core): channel message → approved knowledge → draft reply + case history → permitted actions → escalation when evidence is missing. We are not starting from a blank repo. The paid work is customization under your stack: your channel, CRM, approved answer sources, and the actions that need human confirmation. First customization pilot I would lock: one channel, approved knowledge + files, CRM writeback, stop rules for refunds/account changes/unsupported answers. Packaged boundary + how we run that pilot: https://dali.agents.ge/for/upwork/client-inbox?ref=uw-022069443845701876220 If that matches, reply here in Upwork with one channel, one approved source set, and the actions that must always wait for a person. I will confirm fit and send a fixed pilot milestone (or a short paid blueprint if scope is still loose) before any implementation starts. | P17: https://dali.agents.ge/for/upwork/client-inbox?ref=uw-022069443845701876220 | Q17: https://www.upwork.com/jobs/span-class-highlight-span-span-class-highlight-Automation-span-Engineer-Build-Custom-Claude-Customer-Service-span-class-highlight-Agent-span_~022069443845701876220/?referrer_url_path=/nx/search/jobs/ | R17: High confidence; verified client with rating 5 and over $3k spend, but 50+ proposals and a requirement for production communication and MCP or tool-use proof. | T17: Unknown | X17: Not Evaluated | Y17: Unassigned | AE17: =IFERROR((AA17-AD17)/AA17,"") | AG17: Batch C | AH17: Manual Check | AI17: Anonymous direct page was blocked by a Cloudflare challenge. Verify open status and scope inside Upwork. | AJ17: 2026-07-30 03:14 +04 | AK17: =IF(AND(U17<>"",S17=""),"WARN: Reply date without sent date",IF(AND(OR(C17="Sent",C17="Replied",C17="Qualified",C17="Blueprint Proposed",C17="Pilot Proposed",C17="Blueprint Funded",C17="Pilot Funded",C17="Won"),S17=""),"WARN: Stage requires sent date",IF(AND(OR(C17="Replied",C17="Qualified",C17="Blueprint Proposed",C17="Pilot Proposed",C17="Blueprint Funded",C17="Pilot Funded",C17="Won"),U17=""),"WARN: Stage requires reply date",IF(AND(X17="Qualified",U17=""),"WARN: Qualified without reply date",IF(AND(C17="Qualified",X17<>"Qualified"),"WARN: Qualified stage mismatch",IF(AND(X17="Qualified",NOT(OR(C17="Qualified",C17="Blueprint Proposed",C17="Pilot Proposed",C17="Blueprint Funded",C17="Pilot Funded",C17="Won"))),"WARN: Qualified value stage mismatch",IF(AND(Z17>0,NOT(OR(Y17="Blueprint",Y17="Direct Pilot"))),"WARN: Quote without sales path",IF(AND(OR(C17="Blueprint Proposed",C17="Blueprint Funded"),Y17<>"Blueprint"),"WARN: Blueprint stage path mismatch",IF(AND(OR(C17="Pilot Proposed",C17="Pilot Funded"),Y17<>"Direct Pilot"),"WARN: Pilot stage path mismatch",IF(AND(OR(C17="Blueprint Proposed",C17="Pilot Proposed",C17="Blueprint Funded",C17="Pilot Funded",C17="Won"),Z17<=0),"WARN: Offer stage without quote",IF(AND(Z17>0,NOT(OR(C17="Blueprint Proposed",C17="Pilot Proposed",C17="Blueprint Funded",C17="Pilot Funded",C17="Won"))),"WARN: Quote stage mismatch",IF(AND(AA17>0,Z17<=0),"WARN: Funded without quote",IF(AND(OR(C17="Blueprint Funded",C17="Pilot Funded",C17="Won"),AA17<=0),"WARN: Funded stage without amount",IF(AND(AA17>0,NOT(OR(C17="Blueprint Funded",C17="Pilot Funded",C17="Won"))),"WARN: Funded value stage mismatch","OK"))))))))))))))
A18: Wave 1 | B18: Landing Link | C18: Not Sent | D18: Client Inbox | E18: =IF(G18>=90,"A",IF(G18>=80,"B",IF(G18>=70,"C","D"))) | F18: FL.ru:5514909 | G18: 93 | H18: FL.ru | I18: Интеграция GPT и Битрикс для международной логистики | J18: по договоренности | K18: 45 | L18: not saved | M18: Для логистической компании нужна AI-система на базе Битрикс24 и n8n, но текущий процесс описан слишком широко. | N18: Один клиентский канал, один сценарий ответа или действия, запись результата в Битрикс24 и очередь подтверждения для исключений. | O18: GPT + Битрикс24 + n8n для международной логистики: ответы клиентам по утвержденному контексту и запись результата. У нас в Dali Agency уже собрано готовое продуктовое ядро client-inbox: входящее сообщение → утвержденные источники → черновик ответа + история → разрешенные действия → эскалация, если нет опоры. Мы не пишем систему с нуля. Оплачиваемая работа - кастомизация под вас: ваш канал, CRM, базу ответов и действия, которые требуют подтверждения человеком. Первый пилот кастомизации, который я бы зафиксировал: один клиентский сценарий: входящее обращение → ответ по approved-контексту → запись результата в Битрикс24. Упакованная граница пилота и как мы это ведем: https://dali.agents.ge/ru/solutions/client-inbox?ref=fl-5514909 Если граница совпадает, ответьте здесь в проекте FL.ru и пришлите один канал, один набор утвержденных источников и действия, которые всегда ждут человека. Я подтвержу fit и пришлю фиксированный milestone пилота (или короткий платный blueprint, если scope еще рыхлый) до начала реализации. | P18: https://dali.agents.ge/ru/solutions/client-inbox?ref=fl-5514909 | Q18: https://www.fl.ru/projects/5514909/integratsiya-gpt-i-bitriks-dlya-mejdunarodnoy-logistiki-.html | R18: High confidence; 45 ответов, широкий scope, бюджет и acceptance criteria не определены. | T18: Unknown | X18: Not Evaluated | Y18: Unassigned | AE18: =IFERROR((AA18-AD18)/AA18,"") | AG18: Batch B | AH18: Open | AI18: Direct page is open with 48 responses. Scope is broader than one pilot; pitch only the funded commercial-assistant first phase. | AJ18: 2026-07-30 03:13 +04 | AK18: =IF(AND(U18<>"",S18=""),"WARN: Reply date without sent date",IF(AND(OR(C18="Sent",C18="Replied",C18="Qualified",C18="Blueprint Proposed",C18="Pilot Proposed",C18="Blueprint Funded",C18="Pilot Funded",C18="Won"),S18=""),"WARN: Stage requires sent date",IF(AND(OR(C18="Replied",C18="Qualified",C18="Blueprint Proposed",C18="Pilot Proposed",C18="Blueprint Funded",C18="Pilot Funded",C18="Won"),U18=""),"WARN: Stage requires reply date",IF(AND(X18="Qualified",U18=""),"WARN: Qualified without reply date",IF(AND(C18="Qualified",X18<>"Qualified"),"WARN: Qualified stage mismatch",IF(AND(X18="Qualified",NOT(OR(C18="Qualified",C18="Blueprint Proposed",C18="Pilot Proposed",C18="Blueprint Funded",C18="Pilot Funded",C18="Won"))),"WARN: Qualified value stage mismatch",IF(AND(Z18>0,NOT(OR(Y18="Blueprint",Y18="Direct Pilot"))),"WARN: Quote without sales path",IF(AND(OR(C18="Blueprint Proposed",C18="Blueprint Funded"),Y18<>"Blueprint"),"WARN: Blueprint stage path mismatch",IF(AND(OR(C18="Pilot Proposed",C18="Pilot Funded"),Y18<>"Direct Pilot"),"WARN: Pilot stage path mismatch",IF(AND(OR(C18="Blueprint Proposed",C18="Pilot Proposed",C18="Blueprint Funded",C18="Pilot Funded",C18="Won"),Z18<=0),"WARN: Offer stage without quote",IF(AND(Z18>0,NOT(OR(C18="Blueprint Proposed",C18="Pilot Proposed",C18="Blueprint Funded",C18="Pilot Funded",C18="Won"))),"WARN: Quote stage mismatch",IF(AND(AA18>0,Z18<=0),"WARN: Funded without quote",IF(AND(OR(C18="Blueprint Funded",C18="Pilot Funded",C18="Won"),AA18<=0),"WARN: Funded stage without amount",IF(AND(AA18>0,NOT(OR(C18="Blueprint Funded",C18="Pilot Funded",C18="Won"))),"WARN: Funded value stage mismatch","OK"))))))))))))))
A19: Wave 1 | B19: Landing Link | C19: Not Sent | D19: Client Inbox | E19: =IF(G19>=90,"A",IF(G19>=80,"B",IF(G19>=70,"C","D"))) | F19: FL.ru:5513206 | G19: 92 | H19: FL.ru | I19: AI агент | J19: по договоренности | K19: 17 | L19: not saved | M19: Агент в Битрикс24 должен отслеживать открытые линии, разбирать файлы и работать с клиентскими чатами. | N19: Одна открытая линия, один набор файлов и правил ответа, одна запись истории в Битрикс24 и обязательный human review для чувствительных действий. | O19: AI-агент для открытых линий, чатов и файлов внутри Битрикс24. У нас в Dali Agency уже собрано готовое продуктовое ядро client-inbox: входящее сообщение → утвержденные источники → черновик ответа + история → разрешенные действия → эскалация, если нет опоры. Мы не пишем систему с нуля. Оплачиваемая работа - кастомизация под вас: ваш канал, CRM, базу ответов и действия, которые требуют подтверждения человеком. Первый пилот кастомизации, который я бы зафиксировал: одна линия: прочитать обращение и файл → подготовить ответ → записать историю → передать человеку спорные кейсы. Упакованная граница пилота и как мы это ведем: https://dali.agents.ge/ru/solutions/client-inbox?ref=fl-5513206 Если граница совпадает, ответьте здесь в проекте FL.ru и пришлите один канал, один набор утвержденных источников и действия, которые всегда ждут человека. Я подтвержу fit и пришлю фиксированный milestone пилота (или короткий платный blueprint, если scope еще рыхлый) до начала реализации. | P19: https://dali.agents.ge/ru/solutions/client-inbox?ref=fl-5513206 | Q19: https://www.fl.ru/projects/5513206/ai-agent.html | R19: High confidence; 17 ответов, доступ к чатам и файлам, персональные данные и human review требуют отдельной проверки. | T19: Unknown | X19: Not Evaluated | Y19: Unassigned | AE19: =IFERROR((AA19-AD19)/AA19,"") | AG19: Batch C | AH19: Open | AI19: Direct page returned 200 with an active response CTA; Bitrix24, chat, files, OCR, CRM, and human-escalation scope matched. | AJ19: 2026-07-30 03:14 +04 | AK19: =IF(AND(U19<>"",S19=""),"WARN: Reply date without sent date",IF(AND(OR(C19="Sent",C19="Replied",C19="Qualified",C19="Blueprint Proposed",C19="Pilot Proposed",C19="Blueprint Funded",C19="Pilot Funded",C19="Won"),S19=""),"WARN: Stage requires sent date",IF(AND(OR(C19="Replied",C19="Qualified",C19="Blueprint Proposed",C19="Pilot Proposed",C19="Blueprint Funded",C19="Pilot Funded",C19="Won"),U19=""),"WARN: Stage requires reply date",IF(AND(X19="Qualified",U19=""),"WARN: Qualified without reply date",IF(AND(C19="Qualified",X19<>"Qualified"),"WARN: Qualified stage mismatch",IF(AND(X19="Qualified",NOT(OR(C19="Qualified",C19="Blueprint Proposed",C19="Pilot Proposed",C19="Blueprint Funded",C19="Pilot Funded",C19="Won"))),"WARN: Qualified value stage mismatch",IF(AND(Z19>0,NOT(OR(Y19="Blueprint",Y19="Direct Pilot"))),"WARN: Quote without sales path",IF(AND(OR(C19="Blueprint Proposed",C19="Blueprint Funded"),Y19<>"Blueprint"),"WARN: Blueprint stage path mismatch",IF(AND(OR(C19="Pilot Proposed",C19="Pilot Funded"),Y19<>"Direct Pilot"),"WARN: Pilot stage path mismatch",IF(AND(OR(C19="Blueprint Proposed",C19="Pilot Proposed",C19="Blueprint Funded",C19="Pilot Funded",C19="Won"),Z19<=0),"WARN: Offer stage without quote",IF(AND(Z19>0,NOT(OR(C19="Blueprint Proposed",C19="Pilot Proposed",C19="Blueprint Funded",C19="Pilot Funded",C19="Won"))),"WARN: Quote stage mismatch",IF(AND(AA19>0,Z19<=0),"WARN: Funded without quote",IF(AND(OR(C19="Blueprint Funded",C19="Pilot Funded",C19="Won"),AA19<=0),"WARN: Funded stage without amount",IF(AND(AA19>0,NOT(OR(C19="Blueprint Funded",C19="Pilot Funded",C19="Won"))),"WARN: Funded value stage mismatch","OK"))))))))))))))
A20: Wave 1 | B20: Landing Link | C20: Not Sent | D20: Client Inbox | E20: =IF(G20>=90,"A",IF(G20>=80,"B",IF(G20>=70,"C","D"))) | F20: Upwork:~022081818297985759122 | G20: 70 | H20: Upwork | I20: n8n AI Automation Specialist for Chatbot | J20: Hourly: $19-$40 | K20: 20 to 50 | L20: yesterday | M20: An omnichannel assistant called Sara must use n8n, RAG, and web chat across several customer platforms, but the channels, sources, CRM, and quality criteria are not named. | N20: One customer channel, one approved knowledge set, one CRM or case-history destination, and one escalation queue. | O20: Sara needs an omnichannel assistant with RAG, n8n, and controlled customer replies - not an unsupervised chatbot. We already have a production-ready product core for this at Dali Agency (client-inbox core): channel message → approved knowledge → draft reply + case history → permitted actions → escalation when evidence is missing. We are not starting from a blank repo. The paid work is customization under your stack: your channel, CRM, approved answer sources, and the actions that need human confirmation. First customization pilot I would lock: one customer channel, one approved RAG source set, one case-history destination, and a hard escalation rule. Packaged boundary + how we run that pilot: https://dali.agents.ge/for/upwork/client-inbox?ref=uw-022081818297985759122 If that matches, reply here in Upwork with one channel, one approved source set, and the actions that must always wait for a person. I will confirm fit and send a fixed pilot milestone (or a short paid blueprint if scope is still loose) before any implementation starts. | P20: https://dali.agents.ge/for/upwork/client-inbox?ref=uw-022081818297985759122 | Q20: https://www.upwork.com/jobs/n8n-Automation-Specialist-for-Chatbot_~022081818297985759122/?referrer_url_path=find_work_home | R20: Medium-high confidence; 20-50 proposals, unverified client, and an under-specified brief with no named channels, sources, CRM, or deliverables. | T20: Unknown | X20: Not Evaluated | Y20: Unassigned | AE20: =IFERROR((AA20-AD20)/AA20,"") | AG20: Batch A | AH20: Open | AI20: Full card accessible and scope matched. 20-50 proposals and client viewed yesterday. | AJ20: 2026-07-30 03:16 +04 | AK20: =IF(AND(U20<>"",S20=""),"WARN: Reply date without sent date",IF(AND(OR(C20="Sent",C20="Replied",C20="Qualified",C20="Blueprint Proposed",C20="Pilot Proposed",C20="Blueprint Funded",C20="Pilot Funded",C20="Won"),S20=""),"WARN: Stage requires sent date",IF(AND(OR(C20="Replied",C20="Qualified",C20="Blueprint Proposed",C20="Pilot Proposed",C20="Blueprint Funded",C20="Pilot Funded",C20="Won"),U20=""),"WARN: Stage requires reply date",IF(AND(X20="Qualified",U20=""),"WARN: Qualified without reply date",IF(AND(C20="Qualified",X20<>"Qualified"),"WARN: Qualified stage mismatch",IF(AND(X20="Qualified",NOT(OR(C20="Qualified",C20="Blueprint Proposed",C20="Pilot Proposed",C20="Blueprint Funded",C20="Pilot Funded",C20="Won"))),"WARN: Qualified value stage mismatch",IF(AND(Z20>0,NOT(OR(Y20="Blueprint",Y20="Direct Pilot"))),"WARN: Quote without sales path",IF(AND(OR(C20="Blueprint Proposed",C20="Blueprint Funded"),Y20<>"Blueprint"),"WARN: Blueprint stage path mismatch",IF(AND(OR(C20="Pilot Proposed",C20="Pilot Funded"),Y20<>"Direct Pilot"),"WARN: Pilot stage path mismatch",IF(AND(OR(C20="Blueprint Proposed",C20="Pilot Proposed",C20="Blueprint Funded",C20="Pilot Funded",C20="Won"),Z20<=0),"WARN: Offer stage without quote",IF(AND(Z20>0,NOT(OR(C20="Blueprint Proposed",C20="Pilot Proposed",C20="Blueprint Funded",C20="Pilot Funded",C20="Won"))),"WARN: Quote stage mismatch",IF(AND(AA20>0,Z20<=0),"WARN: Funded without quote",IF(AND(OR(C20="Blueprint Funded",C20="Pilot Funded",C20="Won"),AA20<=0),"WARN: Funded stage without amount",IF(AND(AA20>0,NOT(OR(C20="Blueprint Funded",C20="Pilot Funded",C20="Won"))),"WARN: Funded value stage mismatch","OK"))))))))))))))
